Workbook

Sheet OP Admin Checklist 
A1: OP Administrative Work Tasks
A3: Item | B3: Task Category | C3: Responsibilities | D3: Frequency | E3: Date performed | F3: Initial | G3: Notes
A4: 1 | B4: Local Admin | C4: Outside lights working status: make sure the lights are working properly during night hours only; If some lights are broken, should contact the vendor to fix or replace immediately; | D4: Weekly
A5: 2 | C5: Landscape status: Ensure the gardener is working according to their schedule and the landscape are maintained in good condition; If any sprinklers are not working properly or any water leaking, should contact the vendor to quote and fix immediately. | D5: Weekly
A6: 3 | C6: Parking lot status: Make sure no unknown/ not-allowed vehicles parking in our yards; Ensure no one change oils or fixing vehicles in our parking lot without permission. | D6: Daily | E6: 9/16/2026,9/23,9/29,9/30 | F6: IZ,ML | G6: Dock #19, has a car parked during lunch time, 9/23 private vehicle parked between dock 24-25, near exit door,9/29-9/30 unkown white trailer parking at yard
A7: 4 | C7: Parking Lot Gate: make sure the gate is working properly. | D7: Daily
A8: 5 | C8: Make sure the outside mail box, loading dock door, outside windows and walls and so on are in good working order. If any improper situation pop up, should report to local manager to resolve. | D8: Quartey
A9: 6 | C9: Check conditions of Roof (if leaking?), HVAC working?, Water Faucet leaking? Lights broker? Windows Cleaned? Pest control performed? If any of the times here has issue, contact local vendor and perform services. | D9: Quartey | E9: 9/18， 9/21， 9/28， 9/29， 9/30 | F9: ML | G9: Pest Control Check In, Reported to Lanlord (Alex): broken docks, roof leaks, broken lights/fan by docks, non working outlets by docks,
A10: 7 | B10: Forklift Maintenance | C10: Maintain and store Forklift Maintain record by Forklift. This includes weekly maintained page and all repairs paperwork. | D10: Weekly | E10: 9/2, 9/10, 9/15,9/16,9/21,9/28 | F10: IZ, YJ, ML | G10: https://onedrive.live.com/personal/21f1717b0dd121e7/_layouts/15/Doc.aspx?sourcedoc=%7BD3B0969C-36EE-478F-95E2-FDC5CB7C53BD%7D&file=new%20forklift%20list%209-28.xlsx&action=default&mobileredirect=true
A11: 8 | C11: Report any services needed and follow through the repair. | D11: Ad hoc | E11: September | F11: ML | G11: created new document for machines and maintenance, shared with wilson and the team to better keep track of damaged machines and repairs: https://docs.google.com/document/d/1ynvTs9DUQkFu2_oMgW9DDgE6prUisMYYImTb8dH9U8M/edit?usp=sharing | H11: https://docs.google.com/document/d/1ynvTs9DUQkFu2_oMgW9DDgE6prUisMYYImTb8dH9U8M/edit?tab=t.0
A12: 9 | B12: Fire Safety | C12: Confirm the extinguisher is visible, unobstructed, and in its designated location. | D12: Monthly | E12: 9/8,9/15,9/16 | F12: JT,YJ
A13: 10 | C13: Verify the locking pin is intact and the tamper seal is unbroken. Examine the extinguisher for obvious physical damage, corrosion, leakage, or clogged nozzle. | D13: Monthly | E13: 9/8,9/15,9/16 | F13: JT,YJ | G13: dock99/100 is broken, l86 does not have one
A14: 11 | C14: Confirm the pressure gauge or indicator is in the operable range or position, and lift the extinguisher to ensure it is still full. | D14: Monthly | E14: 9/8,9/15,9/16 | F14: JT,YJ
A15: 12 | C15: Make sure the operating instructions on the nameplate are legible and facing outward. | D15: Monthly | E15: 9/8,9/15,9/16 | F15: JT,YJ
A16: 13 | C16: Initial and date the back of the tag on a monthly basis. | D16: Monthly | E16: 9/8,9/15,9/16 | F16: JT,YJ
A17: 14 | C17: Check the last professional service date on the tag. (A licensed fire extinguisher maintenance contractor must have inspected the extinguisher within the past 12 months.) (Yearly) | D17: Annually
A18: 15 | B18: Office Supply and Organization | C18: Warehouse supplies ordering: check current inventory and order through HQ Admin; | D18: Weekly | E18: 9/14,9/16,9/18 | F18: ML | G18: Mandy：9/16 gloves and vests for warehouse workers, 9/14 scales for reorder 9/18: propane gloves
A19: 16 | C19: Office Supplies ordering: check current inventory and order through HQ Admin; | D19: Weekly | E19: 9/2,9/4,9/8,9/9,9/10,9/14,9/18,9/21,9/22,9/23,9/24 | F19: ML， IZ | G19: Mandy：9/2: items for new OP(laptop stand, holder, desk mount, trash cans), fly traps for the office due to abundance of fruit flies and flys, 9/8 medicine for Lily, 9/9 more office supplies, post it notes, rubber bands, 9/10 air tags and holders for PDA, 9/11 open/close signs for the metal gate by the road, usb port, 9/14 trash bags 9/18: clorox for cleaning, 9/21-9/22 usb, highlighters, desk organizers, printer paper Isabella：9/4 office supplies, paper towls, alchol wipes for printers, tape for rework 9/23-9/24: printer paper, measuring tape coffee cups, binder clips,
A20: 17 | C20: Collect mails on a weekly basis and make sure important letters, such as letters from government agency, send to HQ Admin, AP and Fiona. | D20: Weekly | E20: 9/2,9/10,9/16,9/18.9/25 | F20: IZ, ML | G20: 9/18: VCE dropped off checks for employees, and said to give it to them
A21: 18 | C21: Ensure office is cleaned on a weekly basis and is maintained neat and organized, | D21: Weekly | E21: 9/4,9/11,9/18,9/25 | F21: IZ, YJ, ML, KIKI | G21: 9/25: Mandy and Isabella organized the storage room. Oragnized any new amazon packages and updated in the ordering sheet. Threw away any broken items/empty boxes.
E26: Manager Sign Off:
E28: Review Date:

Sheet Sub order-JT
A1: Month | B1: 9
A2: Date | B2: Pallets | C2: Time | D2: Notes | E2: date | F2: suborder pallet prepared | G2: note | H2: 46269 | I2: XPO pick up ZY-LMVESMYS-260902-000012 but loaded ZY-LMVESMYS-260903-000012 , so ZY-LMVESMYS-260903-000012 already ship out in system but actual no ship out | M2: create pick list | N2: date | O2: NOTE
E3: 46266 | F3: 2 | Q3: Date | R3: Total number of orders (Based on what's pushed though system daily) | S3: Total number of carton labels | T3: Total time spent on all sub-order related tasks ** | U3: If helped with actual labeling. How many minutes | V3: If order requires additional communication with clients, how much time? | W3: Average efficiency per order *** | X3: Total working hour | Y3: Sub order workload
E4: 46267 | F4: 4 | W4: 0 | X4: 480 | Y4: 0
E5: 46268 | W5: 0 | X5: 480 | Y5: 0
E6: 46269 | W6: 0 | X6: 480 | Y6: 0
W7: 0 | X7: 480 | Y7: 0
W8: 0 | X8: 480 | Y8: 0
A9: 46269 | B9: 16 | C9: 25 | D9: ZY-WY-HJCL-260901-000019, 16, 4, 8, 7, 20, 9, 6, 3, 10, 12, 5,15, 13,17, 14 with yujie | W9: 0 | X9: 480 | Y9: 0
A10: 46269 | B10: 2 | C10: 12 | D10: ZY-WY-HJCL-260902-000001 | W10: 0 | X10: 480 | Y10: 0
A11: 46269 | B11: 1 | C11: 12 | D11: ZY-LMVESMYS-260902-000012 | W11: 0 | X11: 480 | Y11: 0
A12: 46273 | B12: 12 | C12: 35 | D12: ZY-MK-HZYM-260826-000001 | W12: 0 | X12: 480 | Y12: 0
A13: 46273 | B13: 2 | C13: 20 | D13: ZY-LMVESMYS-260904-000002, ZY-LMVESMYS-260903-000004 | W13: 0 | X13: 480 | Y13: 0
W14: 0 | X14: 480 | Y14: 0
W15: 0 | X15: 480 | Y15: 0
W16: 0 | X16: 480 | Y16: 0
W17: 0 | X17: 480 | Y17: 0
W18: 0 | X18: 480 | Y18: 0
W19: 0 | X19: 480 | Y19: 0
W20: 0 | X20: 480 | Y20: 0
W21: 0 | X21: 480 | Y21: 0
W22: 0 | X22: 480 | Y22: 0
W23: 0 | X23: 480 | Y23: 0
W24: 0 | X24: 480 | Y24: 0
W25: 0 | X25: 480 | Y25: 0
... W34: 0 | X34: 480 | Y34: 0
R37: ** | S37: all sub order related tasks is anything from printing the labels and order, to assign work to driver, to checking accuracy, shipping out order and upload Bol into was)
R38: *** | S38: Although the average efficiency is her for daily. But do not pay too much attention for daily score. We need to look at this KPI in a larger scale so weekly is the smallest aggregate you should look at.
R41: Suborder Error Tracking
Q42: Date | R42: Order Number | S42: Error description (description what was wrong, and how many qty )

Sheet Sub order-kiki
A1: Month | B1: 9
A2: date | B2: Data related | C2: time(mins) | D2: note | F2: date | G2: load sub order pallet | H2: time(mins) | I2: note | K2: date | L2: suborder pallet prepared | M2: time(mins) | N2: note | P2: date | Q2: new guys set up | S2: date | T2: inbound | V2: date | W2: type | X2: time(mins) | Y2: QYT | AA2: time spent | AB2: NOTE
A3: 9.12 | B3: 9.9-9.11 “error” | C3: 30 | D3: Compile the “errors ”from weicom and log them in the Google Sheet. | F3: 9.14 | G3: PUT LABEL COVER | H3: 45 | I3: ZY-MMT-260910-000003 | K3: 9.13 | L3: printed&prepared | M3: 80 | N3: 13 pallets | P3: 9.16 | Q3: Martha | S3: 9.12 | T3: learn about inbound‘s SOP | V3: 9.13 | W3: assist Isabella for 工单 | X3: 30
A4: 9.12 | B4: 9.4-9.6 KPI for picking | C4: 150 | D4: Review and revise 9.4-9.6 | F4: 9.14 | G4: pick&load | H4: 30 | I4: ok80,IT49,MN17,WM05 | P4: 9.18 | Q4: Raul velasquez | S4: 9.15 | T4: printed&prepared inbond label&Check for duplicates | V4: 9.15 | W4: cover labels：169labels，openbox41 with sam（工单号：20260915-00002） | X4: 180
A5: 9.14 | B5: 9.12"error"&9.13 error | C5: 30 | D5: Compile the “errors ”from weicom and log them in the Google Sheet. | F5: 9.14 | G5: check in assigned to Yujie | H5: 15 | I5: 11 orders | S5: 9.18 | T5: printed&prepared inbond label&Check for duplicates | V5: 9.18 | W5: 工单：took photos&change SKU for printing&reply
A6: 9.14 | B6: 9.7-9.9 KPI for picking | C6: 120 | D6: Review and revise 9.7-9.9 | F6: 9.15 | G6: check in assigned to Mandy | H6: 5 | I6: 1 orders | S6: 9.18
A7: 9.15 | B7: 9.14 error | C7: 15 | D7: Compile the “errors ”from weicom and log them in the Google Sheet. | F7: 9.16 | G7: pick&load | H7: 10 | I7: OK47
A8: 9.15 | B8: 9.10-9.13 KPI for picking | C8: 120 | D8: Review and revise 9.10-9.13 | F8: 9.17 | G8: pick&load | H8: 30 | I8: pz74,EM13,FW67
A9: 9.16 | B9: 9.15 error | C9: 15 | D9: Compile the “errors ”from weicom and log them in the Google Sheet. | F9: 9.17 | G9: pick&load | H9: 30 | I9: XW73,JR27,AP76,UO87
A10: 9.16 | B10: 9.14-9.17 KPI for picking | C10: 120 | D10: Review and revise 9.14-9.17 | F10: 9.18 | G10: pick&load | H10: 30 | I10: LD87,SU78,WR87
A11: 9.17 | B11: 9.16 error | C11: 15 | D11: Compile the “errors ”from weicom and log them in the Google Sheet. | F11: 9.21 | G11: pick&load | H11: 15 | I11: central 2 pick
A12: 9.17 | B12: 9.18-9.20 KPI for picking | C12: 100 | D12: Review and revise 9.18-9.20
A13: 9.18 | B13: 9.17 error | C13: 15 | D13: Compile the “errors ”from weicom and log them in the Google Sheet.
A14: 9.21 | B14: 9.18"error"&9.20 error | C14: 30 | D14: Compile the “errors ”from weicom and log them in the Google Sheet.
A15: 9.21 | B15: review and revise error | C15: 30 | D15: review and revise error
A16: 9.22 | B16: 9.21 error | C16: 15 | D16: Compile the “errors ”from weicom and log them in the Google Sheet.
A17: 9.22 | B17: review and revise error | C17: 45 | D17: review and revise error
A18: 9.23 | B18: 9.22 error | C18: 15 | D18: Compile the “errors ”from weicom and log them in the Google Sheet.
A19: 9.23 | B19: review and revise error | C19: 45 | D19: review and revise error
A20: 9.24 | B20: 9.23 error | C20: 15 | D20: Compile the “errors ”from weicom and log them in the Google Sheet.
A21: 9.24 | B21: review and revise error | C21: 30 | D21: review and revise error
A22: 9.25 | B22: review and revise error | C22: 20 | D22: Everything has been processed as of the 21st.
A23: 9.28 | B23: error：9.24&9.25&9.27 | C23: 30 | D23: Compile the “errors ”from weicom and log them in the Google Sheet.
F24: 46281 | I24: OK47
F25: 46282 | I25: pz74,EM13,FW67
F26: 46282 | I26: XW73,JR27,AP76,UO87
F27: 18 | I27: LD87,SU78,WR87
F28: 46286 | I28: central 2 pick

Sheet Sub order-Isabella
A1: Month | B1: 9
C2: Isabella +1 for Sep full Attendance
A3: date | B3: load sub order pallet | C3: time(mins) | D3: note | E3: date | F3: suborder pallet prepared | G3: note | H3: Date | I3: new guys set up | M3: Date | N3: Type | O3: QYT | P3: Time spend | Q3: NOTE | T3: Date | U3: create pick list
A4: 46268 | B4: 1 | C4: 5 | D4: ZY-GLX-260831-000007 | E4: 46267 | F4: 4 | M4: 46267 | N4: Other | Q4: Create Sep KPI list with updated driver and scanner | V4: Date | W4: Total number of orders (Based on what's pushed though system daily) | X4: Total number of carton labels | Y4: Total time spent on all sub-order related tasks ** | Z4: If helped with actual labeling. How many minutes | AA4: If order requires additional communication with clients, how much time? | AB4: Average efficiency per order *** | AC4: Total working hour | AD4: Sub order workload
A5: 46268 | B5: 4 | C5: 15 | D5: zy-wh-hjcl-260901-000022/zy-wh-hjcl-260901-000011/zy-wh-hjcl-260901-000021/zy-wh-hjcl-260901-000018 | E5: 46268 | F5: 4 | M5: 9/2/2026-9/4 | N5: Other | O5: for yujie | Q5: 9/2 整个大单操作流程都过了一遍 1. 每天早上要打印当天的新的大单做checklist 2. 按照打出来的list 对应订单打大单， 认识b2b 系统操作， 并且打了一些大单，大单Picklist, 系统pallet label, 增值label, BOL 和填写备注。 BOL 上要有订单号码 和批次号码，提货日期， Picklist 上要有订单操作备注和提货日期， 打完要核对一下label 和BOL是否有对应的信息，防止客人上传错label， 如果不确定托数可以看下BOL上是否有托数显示。 3. 学会查看大单的要求， 例如有没有label， 多少托盘， 打不打托， 要不要盖标之类的。 没有提货日期的要48小时内完成， 有提货日期的在提货前完成。 4. 认识客人， WY， XT， RXO 群里沟通， 其他都是工单沟通 5. 大单如果到了提货日子没有来提的，首先查系统排错， 确认是没有来提走的，就需要通知客人， 例如预约9/1来提，但是9/1没有来， 就可以告诉客人。 6. 取消了的订单一定是要把BOL 拿出来， 然后写Cancel， 再自己保存约1个星期， 因为卡车有可能还会来提， 就可以告诉卡车公司这个订单已取消， 不用慌忙再另外找记录 7. 在”待出库“ order 里面要follow up new BOL 和New label， 8. 定期检查”待出库“的订单 是否和桌子上的BOL相符， 是否会有漏打订单的情况。 （至少一个星期一次） 9. 在系统里assign picker, 如何派单， 例如同样的sku 的订单 小的 可以给同一个人， 要贴很多label的订单可以先发出去，不然可以第1天抓，第二天贴label。 学会使用PDA里的picking， suborder prepare, create trailer, loading , take BOL depart and deduct. 10.suborder prepare ：首先要查看订单里的sku数量， 写下detail， 确认数量和sku对之后，可以操作贴标， 需要看一下scanner 是否懂得操作要求，贴了2-3箱对了之后才能放心去做另外一些事情，之后要定时回来检查，9/2 尝试贴一些小订单标签和pallet label. PDA系统里 pending要0 ， 才能finish all, 如果有缺货的是需要操作，按照实际数量填写， （目前没有缺货的订单所以没有接触。） 查看detail里的pallet list, 确认pallet, 删除多余的pallet， 如果pallet 里的sku数目写错 如何改正。 11. 大单司机来提货，一定要核对到3个地方才能放货， 签名写时间和日期， 问trailer 号码。 PDA里面起车， loading的时候要看是对的trailer 号码才能load， 避免有些提货司机停错 load 错。load 完要拍照片 上传， 然后到trailer list 里拍BOL ， depart 之前在系统里查看配单信息， 确认所有收费信息无误之后再depart。 如果有遗留的地方，需要在depart 前修改完成。 12. 知道在哪里下载已完成的订单的BOL 13 ，知道如何重拍BOL 14. 知道如何处理Abandon 订单 15. sku重测， 用PDA重测， 测量要求要看到从头到尾， 和箱子上的sku 16. 在sku list 里查看重测的照片来确认是否已完成重测 17. 每日需要查看工单并处理。 创建工单， submit agent。 9/3: 18 . 打大单，已经可以独立处理简单的大单， 有架子的库位可以highlight出来。讲解什么情况是op 什么情况是swing 。 “待出库”订单里查看 有BOL 和 有label 更新的订单要打出来。 label后面要写订单号码。 19. 给one drive link 里面有: KPI list , error and bonus list, forklist check list， 开始记录每天自己的kpi： sub order pallet loaded, sub order prepare 和 other 20. 整理每周的Forklift checklist 并更新 Forklift list 21. 每日检查邮件， 回复sub order 相关邮件。如何在系统里查找到对应的订单，如果没在系统找到可以先去BOL桌子找，再找不到就去已出库的BOL里找， 如果还是没有配对到系统订单，就让对方提供更多资讯， 如果有核对到订单 回复的时候需要加上系统订单号， 方便后续followup。 提货预约时间是12pm-3pm, 如果是大的订单可以开放一个早上9:30 到10:30 的时间段。 load 整车托盘基本是30分钟。 如果一天有很多大单提货就需要至少间隔30分钟来约。 22. 告知卡车装车尺寸概念： 查看卡车高度，托盘最高95左右就ok了， 整车正装可以26 托， 侧装30， 一正一侧28 ，标准托盘是40*48*72 23. suborder 备货： 尝试了一托有好多sku的备货，并贴label. 做完的sub order 如何修改备货地点 24. 卡车check in, 有同时好几单的需要在BOL上写下序号， 这样自己不会乱掉， 保证签完名的BOL都是对的， 不会拿重复的回来。 sub order 起车， 找order， 扫托盘装车， 拍照， 拍BOL ， 去系统查看订单的label 信息是否正确，如果不正确就要先修改好， 确认无误之后再发车，deduct。 25. follow up 工单，每天工单要处理好。 26。 系统assign 司机捡大单， 需要告知司机捡完货放哪里， 可以出去指给司机看， 要知道给出去的订单是多少托， 根据托数来安排。 确认司机会使用picking,如果不会就要先教一下再去。 最后做完sub order 区域要整理一下， 货不要block exit， 货不要太靠近dock, 确认dock和门关好。 在系统里可以查看司机的拣货的状态来查看是否已捡完货， 捡完就可以出去检查，完成checking。 27. 如何下载已完成的BOL， 如何重拍BOL 28. 使用PDA 扫描查询库位和库存。 diff， 虚拟库存讲解， mark lost 介绍。 29. 打卡机密码， 新人set up 指纹， driver 和scanner 要qr code 信息， qrcode 信息怎么填（nj7， payrate 之类的） 9/4： 30, 网页里面下载KPI的data， 输入scanner 的kpi ， 下载putaway kpi 要先把异常的数据标黄 不登记， 并告知lead。 31. 没有在预期提货提走的sub order 需要告知客人。 32. 对于需要拍照的suborder 处理， 在扫码打托的时候下面有个地方可以拍照， 要拍到全部sku 以及贴好的label 33. 对于有好几托要贴label的订单， 要预先分好每一托的label， 这样就算出错也只是找一个托盘的错误， 不用全部托盘都找， 尝试贴标， 要先看清楚托盘的模式， 用固定的模式贴整托， 不容易出错和漏 34. 要看sub order 第二页上面的要求， 看仔细清楚。 | AB5: 0 | AC5: 480 | AD5: 0
A6: 46273 | B6: 2 | C6: 10 | D6: ZY-WY-SWNT-260901-000051/ZY-WY-SWNT-260901-000016 | E6: 46269 | F6: 9 | G6: 1 green, 2 mys, 6bhd | AB6: 0 | AC6: 480 | AD6: 0
A7: 46273 | B7: 2 | C7: 10 | D7: ZY-LMVESMYS-260902-000002/ZY-GLX-260902-000005 | E7: 46273 | F7: 10 | AB7: 0 | AC7: 480 | AD7: 0
A8: 46274 | B8: 1 | C8: 5 | D8: ZY-XT-KMC-260904-000001 | E8: 46280 | F8: 18 | M8: 46268 | O8: For Mandy | Q8: 9/3 系统里换sku处理， 如何导入库存， 调整库存， （wy 的 XHX-N-17, XHX-18WA） ， 要查上架日期， 导入库存的时候需要写完整原因和上架日期。 | AB8: 0 | AC8: 480 | AD8: 0
A9: 46274 | B9: 2 | C9: 10 | D9: ZY-LMVESMYS-260903-000007/ZY-LMVESMYS-260904-000005 | E9: 46286 | F9: 2 | AB9: 0 | AC9: 480 | AD9: 0
A10: 46274 | B10: 2 | C10: 10 | D10: ZY-LMVESMYS-260904-000008/ZY-LMVESMYS-260904-000010 | E10: 46288 | F10: 2 | AB10: 0 | AC10: 480 | AD10: 0
A11: 46274 | B11: 4 | C11: 10 | D11: ZY-GLX-260902-000004/ZY-LMVESMYS-260907-000019ZY-LMVESMYS-260907-000022ZY-LMVESMYS-260908-000017 deduct and print extra BOL | M11: 46269 | O11: JT | Q11: JT: XPO pick up ZY-LMVESMYS-260902-000012 but loaded ZY-LMVESMYS-260903-000012 , so ZY-LMVESMYS-260903-000012 already ship out in system but actual no ship out | AB11: 0 | AC11: 480 | AD11: 0
A12: 46275 | B12: 2 | C12: 5 | D12: ZY-BHD-260902-000005 | AB12: 0 | AC12: 480 | AD12: 0
A13: 46275 | B13: 2 | C13: 10 | D13: ZY-LMVESMYS-260907-000016，ZY-LMVESMYS-260908-000008 | M13: 9/7-9/10 yujie | O13: for yujie | Q13: yujie： 大单： 1. 对于多sku 的订单需要在分开label， 并在label后面写好对应的sku， 和贴标要求。 2. 每天做完大单后， 需要通过主页查询剩下未完成的订单， 并查缺补漏， 看看哪些订单实际已完成，但是系统里忘记按scan check了， 需要follow up去完成掉或者第二天补上， 3. 对于又有架子又有地堆的单子可以分开2个人拣货， 如果要分开2个人拣货的，那么第一个司机需要给他一张label 写上这个订单的批次号贴在托盘上， 然后把单子转给第二个司机的时候需要告知第二个司机把货物放在相同批次号的托盘上， 避免2个司机拣货混乱。 4. assign给司机的时候一定要把放的location写好， 如果是新人司机的话就要教一下，确认会用PDA拣货， 当日第一次出去看位置的时候就可以把所有有空位的地方提前规划好， 然后写在sub order 的单子上， 这样不用每次有司机来都去查看。 5。 知道如何scan check 多sku， 或多sku在同一个托盘上的大单。 scan check 如果有漏的地方， 可以按detail里面查看 是漏了哪个sku， 或者漏了哪个托盘， 这样就可以快速知道哪里有问题并进行改正， （wy 的一个colorful 单子 + wy 后面 一个11托的单子 都是多sku， 混托处理的） 6. 大单的缺货处理， picking 那边可以按照实际拣货数量提交， 或者“mark lost”, 然后scan check 的时候就按照实际数量填写，告知客人 ， 根据客人指示在系统里选发货或不发货， 并在remark 里面 写上missing的sku和箱数（wy colorfull 单子 1箱missing） 7. remark 那边不能留空， 就算是不知道pallet info， 都要写need pallet info 而不是留空 。 8. label :是贴标数量（不cover）, cover label 就是盖标数量， 有cover label的订单一定会有重新打托。 9. 做完sub order 需要在picking list 上写上服务内容，并在系统里更新 （例如重新打托多少托， 开箱， 包装这些要算时间和人） 10. loading 要确认司机拍照了， 等看到照片上传好 ， 他们loading里面没有东西了， 再让提货司机走， 避免出现网络异常 照片没上传成功提货司机就走了的情况， 如果有卡住的情况， 可以先用PDA拍照先记录下来。 11. 柜子方面：要确认是当天schedule的柜子才可以收， 需要看Google sheet的container list， 先开始拿pallet label， 等熟悉一点再接柜子 根据POD 拿pallet label， 查看柜子里的sku 的location并更新， 单子上和label 上写上dock 号码， 左上角写到达日期和时间， 确认2张list 和pallet 和pod 是一个柜子号码， 使用PDA 点击到仓， PDA那边也要再次和pod核对柜子号码， 避免多个柜子叠在一起有扫错的情况发生。 每个柜子都需要的6张照片： POD， 没开， seal, 半开， 和全开， 如果是司机开的柜子需要发照片然后上传， 知道在哪里上传照片，和修改照片。 已加上所有卡车公司的群。 12. 知道如何打pallet label ， 只打了RXO的柜子， 和看重复的sku， 并在WR list 上记录。 13. 分label的时候要看下这个柜子的sku是否打全了， 就看下头和尾的sku和纸上的对上没有， 确认2张wr list 的号码和pallet label上的号码是对应的才能夹到一起。 14. 如何查看灭火器。 | AB13: 0 | AC13: 480 | AD13: 0
A14: 46280 | B14: 1 | C14: 5 | D14: ZY-WY-SWNT-260908-000055 | AB14: 0 | AC14: 480 | AD14: 0
A15: 46280 | B15: 26 | C15: 20 | D15: ZY-BHD-260902-000002 emerson load , need put pallet label | M15: 9/14-9/18 | O15: for yujie | Q15: 9/14-9/18 ： 1. 对于截单的大货处理，（rxo 一个大货取消），需要把BOL 拿回来写上取消， 把货物的shipping label 撕掉 并贴上label标记 Cancel need put it back， 知道如何在系统里处理， 只要填做完的信息， 和deduct， 然后assign 人上架， 使用PDA 把大货截单的上架， 可以先上到对应库位的-105 那边， 然后让司机放回去的时候用Quick move更新location 2. 对于架子上箱数少的用op， 箱数多的整箱的需要用swing， 3. 制作每周loading 和 unloading的表格并发邮件， unload 可以2个Team 加起来 和container schedule 里的柜子数目核对一下， loading的需要再次核对， 表格里附上当周白板照片， 日期更新， 文件名更新， 再次检查里面的公式是否正确， 有link到了再可以发。 4. 提示: 大单一样要填pallet used 数量， 不要漏掉。 5. 检查“待出库” 的大单里的BOL 更新并打印 6. 知道怎么打印return putaway list 和label 7. 柜子到了，需要根据柜子里的skulocation 来assign dock 8. 提示： 打完大单一定要核对BOL号码， 不要写错 9. 提示： 大单不要忘记贴label啊， 打wrap前要看picking list，确认所有增值服务已完成再wrap！ 10. 新人check in 打指纹， 填qr code， 做完和HR 讲 11. 输入错误 error 和 bonus KPI， 知道怎么加新人picking， putaway， scanner(scanner 要注意factor） 的表格， 并在Summary 里加上新人。 12. 知道pda盲扫盘点的功能在哪里。 yujie 9/14-9/18 ： 主要还是做sub order 这个部分，会assign， 已经知道在assign的时候要告诉司机放哪里。 知道需要检查sub order 的sku和数量。 也发现了有一单是捡多了一箱，并和司机去处理。对于一个司机提很多订单的时候也有打印信息出来一个个核对， load货的时候有带BOL出去再次核对，避免load错。 群里sub order相关的信息也有去关注， 每天待提货那边的BOL需要及时去打印出来，工单每天也有看， sub order 没来提的也有在催的。 但是还是需要细心一些， BOL订单号有写错，但是因为有写批次号，所以可以锁定到对的订单号， 还有一单label忘记贴了， 工单填完忘记提交。 另外做了scanner，putaway KPI， 和输入错误的kpi， 知道在哪里输入picking错误， 和加分 减分的 地方 名字一定是要一样的。完成了所有灭火器的检查， 有2个地方的灭火器有问题。 | AB15: 0 | AC15: 480 | AD15: 0
A16: 46281 | B16: 1 | C16: 5 | D16: ZY-LMVESMYS-260910-000007 | AB16: 0 | AC16: 480 | AD16: 0
A17: 46281 | B17: 2 | C17: 10 | D17: ZY-WY-HJCL-260908-000002，ZY-WY-NBZY-260911-000001 | AB17: 0 | AC17: 480 | AD17: 0
A18: 46283 | B18: 1 | C18: 5 | D18: WJ94 | M18: 9/14-9/18 | O18: For Mandy | Q18: For Mandy：1. timesheet 里面关于有holiday hours 的人 要写holiday hours 8， 表里面第二个分页里面的人才有 2. 使用PDA 开始 和暂停 小包picking，VC 和SFP 会先开始， 使用电脑也可以开始，暂时 小包picking， 3. 知道如何转派小包picking任务， 页数要选最大， 要全选sku， 全转。 4. 怎么打当日picking的barcode list， 看最右边的create time 就知道哪些是当天的， 然后选择当天的导出barcode ， 使用fit in one page 打印 5. 在小包-订单那边可以通过tracking来查到sku。 6. 做完的suborder 改备货location 7. 司机checking 失误后， 使用调整库存功能来修正， 并发邮件附上图片告知客人， 图片也要上传到inbound list 的对应柜子里的附件 | AB18: 0 | AC18: 480 | AD18: 0
A19: 46287 | B19: 5 | D19: ZY-BHD-260821-000003(AD80) finish in system | AB19: 0 | AC19: 480 | AD19: 0
A20: 46287 | B20: 4 | D20: ky36,qi74,wu71 (2个木箱子加2托）finish in system | AB20: 0 | AC20: 480 | AD20: 0
A21: 46287 | B21: 14 | D21: ig66 (wy的14托）finish in system | M21: 9/14-9/18 | O21: For KIKI | Q21: 9/14-9/18： 1. 每天需要看工单， 看邮件并处理。 2. 有增值服务的需要打印出来， 需要拣货出来的， 需要查好location 并写上。 3. 使用批次库存来查询库存数量和库位和哪个客人， 产品管理里面也可以查那个客人。 4. wy， xt， rxo（LMVESMYS） 这3个群 (已加群），其他工单。 5. 小包袋子收费处理， 首先查sku 看哪个客人， 就知道去那里汇报。 6. 条码扫不出需要盖标的， 先查一下目前库存， 然后可以填写工单和客人确认是否需要盖标，后面要写上目前库存数 7. 入库：首先一定是在当日schedule的柜子才可以收， 只有rxo的柜子是看个数的。 通过入库准备那边查询整个柜子里的sku 的location， 合并和单个的。 通过柜子sku的location， sku数量，每个sku的数量来综合考虑如何assign dock， 柜子最起隔开1-2个dock 放， oversize的可以放中间， 大量的， sku少的 可以放地堆， sku多，少量的可以放架子区。 8.根据pod 拿pallet label, 核对label , wr list 上的号码和pod 一样， 查柜子的sku 的location 并更新， 写上dock 号码， 如果driver open 的就要写driver open, 使用pda 来arrivel： 扫完要核对pda上面的柜子号是要和pod上一样的， 避免很多label 叠在一起扫错， 9. 去仓库里拍unload photo， 拍之前确认pda 上的柜子号码和要拍的柜子号码是一样的，避免有些司机乱停， 如果柜子已经打开了，那么可以核对一下sku 来确认是不是对的柜子，拍完4张照片 按starts unload， 选Team， live unload 和drop讲解。 知道在电脑里怎么上传和修改柜子照片，如果Team 选错就在modify 里面可以修改。 10. 收到卸柜组的纸， 需要在每日柜子list 上的柜子前面写E 并在旁边写上柜子号，Dimas 和wilson的分开上下写， pda上确认是否已完成卸柜和有照片， 如果没有的话就要按finish unload，去补空柜照片， 然后看哪个卡车公司就去报空。 柜子哪里来约的就哪里回复空柜回去，今天已经报了rxo 的柜子， 邮件的等以后的柜子加进去了就可以报空了， 今天邮件回复报空的都加上了， 知道邮件报空的一段话要怎么写。 11. 如果有第二张纸回来就是完成了putaway， 需要在系统里检查是否完成了， 避免司机忘记按完成。 2张纸配对 钉在一起。 12. 对于各个状态， 收货管理里面是如何显示的， 例如：什么都没动就是Appointment， 如果有了预约时间的就是会显示日期，并且知道怎么修改预约日期， pda arrivel了上面显示“unload compete”， pda start unload 网页显示“check”, 要定时查询状态， 如果一个柜子很久没有start unload 就要看看是忘记按了 还是什么情况。 13. 白板更新柜子 （上面dimas 下面wilson）， 写每天的unload 数量， putaway数量怎么算， 和写finish putaway time 14. 每天下班前要制作第二天新的container list， no put 的和no unload的要标记 15. 系统里导出柜子sku list 来查看重复sku， 并更新到list上 16. 进入仓库实地查看入库区， dock 1- 56 ， dock 1-2, 56不用，还有dock 坏了， 前面是地堆，后面架子， 并查看当前哪些dock是方便停柜子， 如果有空柜子已经拿走了就划掉。 17. 大货： 提货司机过来check in， 需要核对到3个地方才ok， 然后签名 写时间和日期， 使用PDA 起车，订单号和批次号要和BOL上的批次， 起完车要再次核对， assign 司机， 拿BOL出去， 看pallet批次号 和起车那边的location 找到对应的订单， ，今天load了一个需要一边贴palletlabel 一边load的订单。 找到订单之后把pick list 拿下来 再次核对 信息是否match，订单号， 批次号， label，reference number都可以核对到的。 司机扫描托盘标签load货，(托盘正装和侧装讲解） 拍照。 根据trailer list 里面的颜色查看是否完成拍照， （白色没开始， 黄色loading， 绿色loading照片已拍好 已完成loading） 确认了有装车照， 绿色了，才可以让提货司机走，关ramp， 关灯，关风扇关dock， 关emergency exit， 每次load 完回去的路上确认所有东西关关关 18. load 完， 打开系统根据订单号或批次号找到b2b 订单， 查看订单信息是否正确，如果有更新的地方需要更新， 更新完成后， PDA 拍BOL， 发走，系统里deduct， 填KPI， 在已完成的订单 旁边“uploaded bol” 里面就可以下载到拍的BOL。 19. 输入daily error or bonus 到error or bonus list 里面 9/15 ： 20. 在BI下载picking KPI 并输入picking的kpi， 核对纸质kpi上，修改对应的机器 op , swing 还是reach，如果有额外修改的要手动修改掉 21. 如何打大单， 看指令， 打bol ， 系统assign司机， 打完要核对pickinglist bol label 上面的信息是否对应， 避免打错， 或者是客人上传错label。 相同sku的订单可以放一起， 方便assign， 大托数的订单可以先发。 assign的时候要告诉司机摆哪里。 22. 根据指令 准备大单， 使用PDA做scan check 到备货完成， 在“待提货”里查看没有打印的BOL订单， 所有有更新BOL 的订单都需要查看是否有托盘label 更新， 并一起打出来， label 后面要写批次号， bol上面要贴note 写上要贴托盘标签。 23. 从BI里下载picking kpi 并填写到kpi里， 和纸质版本核对， 改正机器类型， 和根据群里的要求改正对应的picking 时间。 24. 知道怎么加新人picking， putaway， scanner(scanner 要注意factor） 的表格， 并在Summary 里加上新人。 25. 大单截单处理， pda里重新上架 26. 打rxo 的pallet label， 并看重复sku 27. 工单处理： 1. 拍照 2.换sku 处理 ： 调整库存， 库存导入， 库存导入要看上架的日期。 3. 盖标处理：一箱多件产品外箱不能有sku的barcode， 一箱多件产品测量都是测件数。 所有工单要求打印出来， 一张纸一个工单， 并记录每个工单需要回复的收费内容， 例如多少标签， 多少托数，或者工时。 28. 使用新的预约功能预约柜子。 29. 知道pda盲扫盘点的功能在哪里。 | AB21: 0 | AC21: 480 | AD21: 0
A22: 46288 | B22: 4 | C22: 15 | D22: ZY-MGL-260921-000001,ZY-MGL-260921-000003,ZY-MGL-260922-000005 , 加小包ceva | AB22: 0 | AC22: 480 | AD22: 0
A23: 46288 | B23: 3 | D23: xa92,es73,yu85 deduct and 发车 | AB23: 0 | AC23: 480 | AD23: 0
A24: 46289 | B24: 4 | D24: gl98,po19,xq85,aw17 | AB24: 0 | AC24: 480 | AD24: 0
A25: 46289 | B25: 2 | C25: 10 | D25: ZY-GLX-260921-000006, ZY-GLX-260921-000004 | M25: 9.21-9.25 | O25: For KIKI | Q25: 整理每周forklift checklist并更新forklift 列表。 -开始接柜子， 已掌握如何assign dock ，根据每日container dock list 也能基本判断出来哪些dock 可用， 跟从Ismael给的dock位置 结合柜子里sku来安排。 下午只剩几个柜子的时候有和Ismael 沟通提前根据location安排好dock。 -报空：需要查清楚柜子是哪个卡车公司的， 有报错的情况。或者是想报空结果柜号复制错。 -写白板：可以分清dimas 和 Wilson柜子， 知道如何计算每日unload 和putaway数量。 -上传柜子照片并知道如何删除照片，更改卸柜team。 -每天早上和下午去外面看柜子，看dock 上的，（Mandy 看yard的 她们2个人合作看） -管理每日wr list，司机交回时确认putaway 在系统里完成。 有漏交的纸要及时询问。 —Kpi 方面 ：这周KiKi是输入error，但是有error放错了表格的情况。例如：Lucas 里有个chapin的错误。 -开始制作10月份kpi的表格，picking 和putaway 的数量和时间那边加了公式，只要输入总表内容， 分表自动更新， 这个新方式会在10月kpi 中实验，希望可以提升输入kpi的效率。 sub order方面：这周没有出去备货，只是check in 司机和起车。 | AB25: 0 | AC25: 480 | AD25: 0
A26: 46289 | B26: 8 | C26: 20 | D26: ZY-MMT-260921-000001, 一边load | M26: 9.21-9.25 | O26: For Mandy | Q26: Mandy： 这周有打一些sub order的单子，和出去做sub order。对sub order 备货方面更加了解了， 对于一托好几个sku，大批量单个sku，大批量多个sku 的备货都知道如何处理。 Kpi方面：根据总表录入了picking 的kpi。 入库方面： 这周是线下和线上交接的星期， 邮件方面还是要处理和回复，让对方通过系统来预约。 辅助kiki接柜子的时候拿pallet label 和查location。审核pending预约的柜子。 打pallet label。 admin方面：跟进forklift， dock，dock 灯 风扇修理事宜，amazon买的东西，timecard 更正，办公室整理，准备10 月HR 要来检查的东西。 | AB26: 0 | AC26: 480 | AD26: 0
A27: 46290 | B27: 3 | C27: 15 | D27: " ZY-LMVESMYS-260922-000009,ZY-BHD-260924-000001,ZY-BHD-260924-000004"Sanchez load | M27: 9.21-9.25 | O27: For Yujie | Q27: Yujie： sub order： 系统打大单方面没有问题了， 对于有问题的label 也会及时提问。这周给他独立决策派发sub order 的单子， 安排得可以。但是要关注一下捡货司机的状态（就是捡出来了没有，捡到哪个订单了 这些是可以在系统里看到的）。 单子比较多的时候还是他先在外面做sub order， 然后有picker来了， 我再把剩下的单子发给司机。 有同时sub order 在做和司机来提货的情况， 我们一起配合，他load完，我回去拍bol 发车，deduct 完成系统。 有一个托盘发出的时候没有贴上pallet label， 因为他打印了，是要去贴的，同时司机也来拿，就漏贴。 已回工单给客人汇报，客人也没有说什么。 但是经历过这次的情况，他以后每个需要贴pallet label 的托盘上都有标记：need pallet label，以防他再次忘记，失误之后会自己想办法防止再次失误。 -知道如何处理ceva的小包发货， 和打return putaway list sub order 的邮件有回复，看工单，每日催提，跟进bol 更新和 pallet label 更新 柜子方面： 还只是之前的初步了解。 Kpi 方面： 根据纸质picking list 来核对调整picking 的kpi ， 就是把架子的list 挑出来，看看系统是否已写对类型了，如果没有就要修改。 增值服务： 星期五做了个贴胶带的增值服务， 知道需要记录时间和人数， 学习了如何调整和导入库存。 | AB27: 0 | AC27: 480 | AD27: 0
A28: 46294 | B28: 1 | C28: 8 | D28: ZY-LMVESMYS-260925-000002 | M28: 9.21-9.25 | Q28: Kpi 的scanner 表格这周9.21-9.25 做了升级， 只需要在总表输入内容， 分表会自动带出数据， 星期五和yujie 也尝试了是可以的， 这样就只要复制一次， 然后每个表格数据核对一下， 省去了每个表格要多次复制和粘贴的重复工作。 | AB28: 0 | AC28: 480 | AD28: 0
A29: 46294 | B29: 5 | C29: 15 | D29: lm70,dv72,ts91 | AB29: 0 | AC29: 480 | AD29: 0
A30: 46295 | B30: 1 | C30: 5 | D30: ZY-MGL-260929-000008 | M30: 46293 | Q30: putaway kpi ，follow up 工单, forklift check list， 超期找回 | AB30: 0 | AC30: 480 | AD30: 0
A31: 46295 | B31: 2 | C31: 10 | D31: ZY-MGL-260929-000074,ZY-MGL-260929-000075 | M31: 46294 | Q31: put error, scanner double check picking kpi，follow up 工单,print sub order，超期找回 | AB31: 0 | AC31: 480 | AD31: 0
A32: 46295 | B32: 2 | C32: 10 | D32: cn18,FT09 | M32: 46295 | Q32: put error, follow up 工单，wy群里要贴标的sku, 准备HR要的pick 和putaway list,print pallet label and duplicates，超期找回， prepare sub order | AB32: 0 | AC32: 480 | AD32: 0
AB33: 0 | AC33: 480 | AD33: 0
AB34: 0 | AC34: 480 | AD34: 0
AB35: 0 | AC35: 480 | AD35: 0
W38: ** | X38: all sub order related tasks is anything from printing the labels and order, to assign work to driver, to checking accuracy, shipping out order and upload Bol into was)
W39: *** | X39: Although the average efficiency is her for daily. But do not pay too much attention for daily score. We need to look at this KPI in a larger scale so weekly is the smallest aggregate you should look at.
W42: Suborder Error Tracking
V43: Date | W43: Order Number | X43: Error description (description what was wrong, and how many qty )

Sheet Sub order-yujie
A1: Month | B1: 9
D2: Yujie - 3 (9/2,9/3,9/10 late)
A3: date | B3: load sub order pallet | C3: time(mins) | D3: note | E3: date | F3: suborder pallet prepared | G3: note | H3: Date | I3: new guys set up | K3: Date | L3: create pick list | M3: Date | N3: Type | O3: QYT | P3: Time spend | Q3: NOTE
A4: 46268 | B4: 4 | C4: 15 | D4: zy-wh-hjcl-260901-000022/zy-wh-hjcl-260901-000011/zy-wh-hjcl-260901-000021/zy-wh-hjcl-260901-000018 | E4: 46267 | F4: 5 | G4: 1 green pallet, 2 wood pallet . 2 wy | H4: 46279 | I4: kiki | X4: Date | Y4: Total number of orders (Based on what's pushed though system daily) | Z4: Total number of carton labels | AA4: Total time spent on all sub-order related tasks ** | AB4: If helped with actual labeling. How many minutes | AC4: If order requires additional communication with clients, how much time? | AD4: Average efficiency per order *** | AE4: Total working hour | AF4: Sub order workload
A5: 46268 | B5: 11 | D5: 11 PALLETS: ZY-MGL-260901-000011, ZY-MGL-260901-000014, ZY-MGL-260901-000016, ZY-MGL-260901-000008 , ZY-MGL-260901-000015, ZY-MGL-260901-000013, ZY-MGL-260901-000012 , ZY-MGL-260901-000009, ZY-MGL-260901-000010, ZY-MGL-260901-000007 , ZY-MGL-260901-000006 | E5: 46268 | F5: 4 | G5: warpping up for 2 labeling for 4 | H5: 46281 | I5: juan pevez | AD5: 0 | AE5: 480 | AF5: 0
A6: 46269 | B6: 1 | D6: load with jt ZY-LMVESMYS-260902-000010, | F6: 15? | G6: can't remember, 3 box 2 green, and etc | AD6: 0 | AE6: 480 | AF6: 0
A7: 46269 | B7: 5 | C7: 20 | D7: ZY-MMT-260901-000001 | AD7: 0 | AE7: 480 | AF7: 0
A8: 46269 | B8: 16 | C8: 20 | D8: ZY-WY-HJCL-260901-000019, 16, 4, 8, 7, 20, 9, 6, 3, 10, 12, 5,15, 13,17, 14with JT | AD8: 0 | AE8: 480 | AF8: 0
A9: 46269 | B9: 5 | C9: 10 | D9: TYOO 5 PALLETS | AD9: 0 | AE9: 480 | AF9: 0
A10: 46269 | B10: 2 | C10: 8 | D10: ZY-WY-HJCL-260902-000001 checked in assigned to JT | AD10: 0 | AE10: 480 | AF10: 0
A11: 46274 | B11: 1 | C11: 5 | D11: ZY-LMVESMYS-260904-000009 | AD11: 0 | AE11: 480 | AF11: 0
A12: 46274 | B12: 30ish? | C12: ? | D12: ZY-GLX-260902-000004/ZY-LMVESMYS-260907-000019ZY-LMVESMYS-260907-000022ZY-LMVESMYS-260908-000017 | E12: 46274 | F12: 30? | G12: can't remember, too much | AD12: 0 | AE12: 480 | AF12: 0
A13: 46275 | B13: 7 | C13: 30 | D13: ZY-ERB-260907-000001，ZY-LMVESMYS-260907-000031 ，ZY-LMVESMYS-260907-000028 ，ZY-LMVESMYS-260904-000014 ，ZY-LMVESMYS-260903-000018， ZY-BHD-260902-000003 | E13: 46275 | F13: 6 | AD13: 0 | AE13: 480 | AF13: 0
A14: 46275 | B14: 6 | C14: 20 | D14: NX35,HN22,TY29,PO67,FP19,RI20, | AD14: 0 | AE14: 480 | AF14: 0
A15: 46276 | B15: 20? | D15: mf54,ls48,fs97,sk58,ry08,pn27,sd82,ir09,fz96,xu10,ba76, wu35,gu58, container list used. mandy's account to upload the BOL | E15: 46335 | F15: 6 | AD15: 0 | AE15: 480 | AF15: 0
A16: 46279 | B16: 4 | C16: 8 | D16: ok80,IT49,MN17,WM05 | AD16: 0 | AE16: 480 | AF16: 0
A17: 46279 | B17: 20 | C17: 30 | D17: ve57,ip47,pb94,od34,ao76,xs04,sn25,sl66,tf02 | AD17: 0 | AE17: 480 | AF17: 0
A18: 46280 | B18: 11 | D18: ZY-WY-YCDZ-260910-000002 | AD18: 0 | AE18: 480 | AF18: 0
A19: 46280 | B19: 4 | D19: eb69,vf63 (jb hunt) | AD19: 0 | AE19: 480 | AF19: 0
A20: 46280 | B20: 20ISH | C20: 40 | D20: lc29,ji60,fh45,gv52,yy50,ek21,jf66,sf95,kr58,xu67,wb53,qn46 | AD20: 0 | AE20: 480 | AF20: 0
A21: 46280 | B21: 1 | C21: 10 | D21: PD68, | E21: 46280 | F21: 20ish | G21: can't remember, too much | AD21: 0 | AE21: 480 | AF21: 0
A22: 46280 | B22: 0 | C22: 60 | D22: checking fire extinguisher | E22: 46281 | F22: 6 | G22: ZY-MGL-260916-000005, ZY-MGL-260916-000004, ZY-LMVESMYS-260916-000013, ZY-LMVESMYS-260916-000012, ZY-LMVESMYS-260916-000003, checking fire exitingguisher, doing error KPI FROM 9/6/2026 TO 9/9
A23: 46281 | B23: 2 | C23: 10 | D23: qu28,ex59 | E23: 46282 | F23: not sure, 7 orders | G23: ZY-WY-KLGJ-260917-000002, ZY-LMVESMYS-260917-000017, ZY-MMT-260917-000005, ZY-LMVESMYS-260917-000008, ZY-LMVESMYS-260917-000005, ZY-LMVESMYS-260917-000003, ZY-MMT-260917-000003, input kpi scanner from 9/13- 9/16,input KPI erros from 9/9-9/15, | AD23: 0 | AE23: 480 | AF23: 0
A24: 46281 | B24: 4 | C24: 10 | D24: ZY-MGL-260916-000005, ZY-MGL-260916-000004, ZY-MGL-260911-000031, ZY-MGL-260915-000006 | E24: 46283 | F24: 3 | G24: mys-260918-000008,mys-260918-000007,ivn-260918-000001, input KPI erros from 9/15 - 9/ | AD24: 0 | AE24: 480 | AF24: 0
A25: 46282 | B25: 1 | C25: 10 | D25: UK84 checked in by kiki, loaded myself, | E25: 46283 | F25: 5 | G25: rework mmt-260917-000005 | AD25: 0 | AE25: 480 | AF25: 0
A26: 46282 | B26: 1 | C26: 10 | D26: yk78 | E26: 46286 | F26: not sure 17 orders | G26: suborder prepared | AD26: 0 | AE26: 480 | AF26: 0
A27: 46282 | B27: 26 | C27: 60 | D27: hz86,om40,up00,vm06,da85,mt87,xd60,pq83,za11,uo52,pj14,ks60,om14,vr31,cr71,jz08,ci13 | E27: 46287 | F27: est 32pallets | G27: ZY-MGL-260922-000005 ZY-GLX-260922-000004 ZY-GLX-260922-000004 ZY-GLX-260922-000004 ZY-GLX-260922-000004 ZY-GLX-260922-000004 ZY-GLX-260922-000003 ZY-GLX-260922-000002 ZY-GLX-260922-000001 ZY-BHD-260922-000001 ZY-LMVESMYS-260922-000011 ZY-LMVESMYS-260922-000009 ZY-LMVESMYS-260922-000009 ZY-LMVESMYS-260922-000009 ZY-LMVESMYS-260922-000009 ZY-LMVESMYS-260922-000008 ZY-LMVESMYS-260922-000008 ZY-LMVESMYS-260922-000008 ZY-LMVESMYS-260922-000008 ZY-LMVESMYS-260922-000008 ZY-LMVESMYS-260922-000008 ZY-LMVESMYS-260922-000002 ZY-MK-HZYM-2-260922-000001 ZY-WSK-260922-000002 ZY-WY-SWNT-260922-000058 ZY-MK-HZYM-260922-000001 | AD27: 0 | AE27: 480 | AF27: 0
A28: 46283 | B28: 1 | C28: 10 | D28: lk65 | E28: 46288 | F28: 8 orders | G28: ZY-WY-SWNT-260923-000011 ZY-WY-SWNT-260923-000010 ZY-WY-SWNT-260923-000002 ZY-LMVESMYS-260923-000004 ZY-GLX-260923-000002 ZY-IVN-260923-000001 ZY-BHD-260923-000002 ZY-BHD-260923-000001 input scaner kpi from 9/19 - 9/22, new order ZY-MK-MKSEA001-260923-000001 prepared, organized pickers list Equipment 9/18, | AD28: 0 | AE28: 480 | AF28: 0
A29: 46283 | B29: 1 | C29: 5 | D29: KE68 | E29: 46288 | F29: 1 WALMART ORDER | G29: REWORK OF WALMART BIG ORDER at least of 6 pallet | AD29: 0 | AE29: 480 | AF29: 0
A30: 46283 | B30: 3 | C30: 10 | D30: mk97 | E30: 46289 | G30: CREATED: ZY-BHD-260924-000004 ZY-GLX-260924-000001 ZY-MGL-260924-000004 ZY-BHD-260924-000002 ZY-LMVESMYS-260924-000004 ZY-WY-SZYDJ-260924-000001 ZY-ERB-260924-000002 ZY-MMT-260924-000001 ZY-BHD-260924-000001 rework palletized of ej38, | AD30: 0 | AE30: 480 | AF30: 0
A31: 46283 | B31: 4 | C31: 10 | D31: mn62,yn39,rx33,ge65 | E31: 46290 | F31: 5 | G31: LABELING OF EN08 | AD31: 0 | AE31: 480 | AF31: 0
A32: 46286 | B32: 1 | C32: 5 | D32: sb48 | E32: 46290 | F32: 2 | G32: CREATED: ZY-LMVESMYS-260925-000002, ZY-LMVESMYS-260925-000007 | AD32: 0 | AE32: 480 | AF32: 0
A33: 46286 | B33: 1 | C33: 5 | D33: pd93 | E33: 46290 | G33: ORGANIZED PICKERS KPI 9/22 AND CORRECTED the equiment they used | AD33: 0 | AE33: 480 | AF33: 0
A34: 46286 | B34: 2 | C34: 10 | D34: us00,eo44 checked in, loaded by oscar | E34: 46293 | F34: 18 orders | G34: created: ZY-GLX-260928-000002 ZY-GLX-260928-000001 ZY-LMVESMYS-260928-000028 ZY-LMVESMYS-260928-000027 ZY-LMVESMYS-260928-000025 ZY-LMVESMYS-260928-000023 ZY-LMVESMYS-260928-000022 ZY-LMVESMYS-260928-000020 ZY-LMVESMYS-260928-000019 ZY-LMVESMYS-260928-000016 ZY-LMVESMYS-260928-000014 ZY-LMVESMYS-260928-000013 ZY-LMVESMYS-260928-000012 ZY-LMVESMYS-260928-000011 ZY-LMVESMYS-260928-000010 ZY-LMVESMYS-260928-000009 ZY-LMVESMYS-260928-000007 ZY-GLX-260926-000001 assigned sanchez to pick. scan check, label, wrap: qq15, fs35, rw23, tu40, ft09, cn18,hw18； label: sr83, eq09, fs08, kd36, si50 | AD34: 0 | AE34: 480 | AF34: 0
A35: 46288 | B35: 5 | D35: ZY-BHD-260821-000003(AD80) | E35: 46294 | F35: 20 orders | G35: can't remember, too much | AD35: 0 | AE35: 480 | AF35: 0
A36: 46288 | B36: 4 | D36: ky36,qi74,wu71 (2个木箱子加2托） | E36: 46295 | F36: 8 orders | G36: created : ZY-MGL-260930-000035 ZY-MGL-260930-000034 ZY-MGL-260930-000014 ZY-MGL-260930-000013 ZY-MGL-260930-000012 ZY-LMVESMYS-260930-000009 ZY-LMVESMYS-260930-000003 ZY-LMVESMYS-260930-000001 | AD36: 0 | AE36: 480 | AF36: 0
A37: 46288 | B37: 14 | D37: ig66 (wy的14托） | E37: 46295 | G37: input pickers kpi
A38: 46288 | B38: 1 | D38: cp57
A39: 46288 | B39: 4 | C39: 30 | D39: ja42,an30,zp16,ly25 loaded by tix | Y39: ** | Z39: all sub order related tasks is anything from printing the labels and order, to assign work to driver, to checking accuracy, shipping out order and upload Bol into was)
A40: 46288 | B40: 3 | D40: xa92,es73,yu85 3个木箱子 | Y40: *** | Z40: Although the average efficiency is her for daily. But do not pay too much attention for daily score. We need to look at this KPI in a larger scale so weekly is the smallest aggregate you should look at.
...

Sheet Sub order-Mandy
A1: Month | B1: September
C2: Mandy -1 ，9/1 late
A3: date | B3: load sub order pallet | C3: time(mins) | D3: note | F3: date | G3: suborder pallet prepared | H3: note | J3: date | K3: new guys set up | M3: date | N3: inbound | P3: date | Q3: type | R3: QYT | S3: time spent | T3: NOTE
A4: 46266 | B4: 3 | C4: 10 | D4: ZY-LMVESMYS-260828-000004, ZY-LMVESMYS-260827-000005, ZY-LMVESMYS-260828-000009 check in assigned to JT | F4: 46286 | G4: KS64 | J4: 46267 | K4: Glasmary Ortega (GL) | P4: 46268 | Q4: Email/Phone | S4: 10 minutes | T4: Machine #52 Serial:960-26-0012315 Model:960-CSR30T, PO: 090326-CSR30T - notified Wilson and made an appointment with Raymond for Technician to come out | AA4: Date | AB4: Total number of orders (Based on what's pushed though system daily) | AC4: Total number of carton labels | AD4: Total time spent on all sub-order related tasks ** | AE4: If helped with actual labeling. How many minutes | AF4: If order requires additional communication with clients, how much time? | AG4: Average efficiency per order *** | AH4: Total working hour | AI4: Sub order workload
A5: 46266 | B5: 1 | C5: 5 | D5: ZY-RBK-260828-000001 check in assigned to JT | F5: 46286 | G5: VW79 | J5: 46268 | K5: Fernando Tiniganay (Driver) | P5: 46268 | Q5: Driver check in - Inbound | S5: 20 minutes | T5: imported container photos to WMS | AG5: 0 | AH5: 480 | AI5: 0
A6: 46266 | B6: 1 | C6: 5 | D6: ZY-WY-SZYDJ-260827-000001 checked in assigned to JT | F6: 46286 | G6: MQ67 (2 pallets) | J6: 46274 | K6: Oscar Cuevas (Driver) | P6: 46268 | Q6: Driver check in-Outbound | S6: 10 minutes | T6: helped check info on 11 Amazon BOL, JT signed and put into PDA, Yujie loaded | AG6: 0 | AH6: 480 | AI6: 0
A7: 46266 | B7: 2 | C7: 8 | D7: ZY-LMVESMYS-260828-000003, ZY-LMVESMYS-260828-000010 checked in assigned to JT | F7: 46287 | G7: MV47 | J7: 46294 | K7: Merkin Samayoa (Scanner) | P7: 46269 | Q7: Other | S7: 15 minutes | T7: called amerigas to confirm labor day hours and reschedule monday delivery to tuesday | AG7: 0 | AH7: 480 | AI7: 0
A8: 46266 | B8: 2 | C8: 10 | D8: ZY-WY-SWNT-260825-000039, ZY-IVN-260829-000002 checked in assigned to JT | F8: 46287 | G8: MT73 | J8: 46295 | K8: David Gonzalez (Driver) | P8: 46273 | Q8: Email | S8: 10 minutes | T8: sent empty emails of the containers unloaded over the weekend | AG8: 0 | AH8: 480 | AI8: 0
A9: 46274 | B9: 1 | C9: 5 | D9: ZY-LMVESMYS-260904-000009 check in assigned to Isabella | F9: 46287 | G9: AW17 | P9: 46273 | Q9: Other | S9: 60 minutes | T9: completed duplicates for RXO, Monday containers, and attached to labels | AG9: 0 | AH9: 480 | AI9: 0
A10: 46274 | B10: 2 | C10: 8 | D10: ZY-LMVESMYS-260904-000005, ZY-LMVESMYS-260903-000007 check in，assigned to Isabella， Isabella 汽车 | F10: 46287 | G10: XQ85 | P10: 46273 | Q10: Other | T10: -in the morning checked dock and yard for containers before coming inside and clocking in -accepted 18 containers throughtout the day, checking in the container, checking WR for updated locations, and taking pictures of POD -uploaded containers and seal photos 6 in the morning, 5 in the afternoon, also uploaded some that came late on Friday and was unloaded and putaway on the weekend -stapled loading and unloading, making sure the amount of putaway was correct from Friday and the weekend -sent cleaning invoice email -set up new employee in UAccess and prepared new items like walkie talkie, vests, pens, gloves -printed the remainder of the weeks' labels and WR -sent emails and followups with Wilson and corresponding companies in regards to broken machines, also notified Isabella and Amanda - 23 emails and scheduling | AG10: 0 | AH10: 480 | AI10: 0
A11: 46274 | B11: 4 | C11: 12 | D11: ZY-GLX-260902-000004, ZY-LMVESMYS-260907-000022, ZY=LMVESMYS-260908-000017, ZY-LMVESMYS_260907-000019, check in, Isabella 汽车 | F11: 46287 | G11: XQ85 | P11: 46274 | T11: -in the morning checked dock and yard for containers before coming inside and clocking in -accepted 23 containers throughtout the day, checking in the container, checking WR for updated locations, and taking pictures of POD -organize the labels with the WR and set them on the table -print remaining containers coming during the week that was scheduled on Monday -1 hour combined printing and doing duplicates and preparing them for the rest of the week -sent empty emails that finished unloading -scheduled containers and double checked if it is in the system -help with scanner interview, timed the "find what is the difference" portion -comepleted whiteboard | AG11: 0 | AH11: 480 | AI11: 0
A12: 46274 | B12: 2 | C12: 10 | D12: ZY-LMVESMYS-260904-000008, ZY-LMVESMYS-260904-000010, check in assigned to Yujie | F12: 46287 | G12: MQ67 | H12: finished the remaining pallets with the labels and repalletized | P12: 46275 | T12: -in the morning checked dock and yard for containers before coming inside and clocking in -accepted 23 containers throughtout the day, checking in the container, checking WR for updated locations, and taking pictures of POD -staple loading and unloading, making sure the correct number of putaways were done -sent empty emails, wecom, wechat notifications after the containers were unloaded -created and organized RXO appointments in the schedule and sent emails to Best and SSR -started to print next week's labels, added on dka container schedules from email -uploaded container and seal photos (10) for about 20 minutes in the morning -sent general and overview of empties from the day before to corresponding trucking companies, 15 minutes -emailed some trucking companies asking for container and seal photos since the driver did not send when told to or was opened by them outside -spent about 25 minutes on work tickets -rescheudled GESU6086259, who called and rescheudled the container -spent about an hour on email responses, scheduling, and any followups -sent emails in regards to broken swing and forklifts -30 minutes on RXO scheudling -created new maintenance and machines document to better track machines that are broken and fixed (https://docs.google.com/document/d/1ynvTs9DUQkFu2_oMgW9DDgE6prUisMYYImTb8dH9U8M/edit?tab=t.0) -20ish minutes with setting up large PDA, installing Apple Airtag, and assignment to drivers | U12: https://docs.google.com/document/d/1ynvTs9DUQkFu2_oMgW9DDgE6prUisMYYImTb8dH9U8M/edit?tab=t.0 | AG12: 0 | AH12: 480 | AI12: 0
A13: 46276 | B13: 1 | C13: 5 | D13: ZY-LMVESMYS-260909-000001, check in assigned to Yujie | F13: 46288 | G13: MQ67 | H13: calculated pallet weight of all 8 pallets and finished preparing in system | P13: 46276 | T13: -in the morning checked dock and yard for containers before coming inside and clocking in -accepted 16 containers throughtout the day, checking in the container, checking WR for updated locations, and taking pictures of POD -staple loading and unloading, making sure the correct number of putaways were done -sent empty emails, wecom, wechat notifications after the containers were unloaded -spent about 20 minutes on uploading container and seal photos from the day before and the day of, 10 uploaded -emailed trucking company for photos due to driver forgetting to send, or was opened when it did not need to (3454, 6238, 5379, 7866) -spent about 20 minutes sending general empties to corresponding trucking companies -about 20 minutes on emails and work tickets, created appointments -10 minutes organizing desk area and desk in surrounding areas -print more labels and did duplicates | AG13: 0 | AH13: 480 | AI13: 0
A14: 46276 | B14: 3 | C14: 10 | D14: Zy-LMVESMYS-260908-000007, ZY-LMVESMYS-260907-00009, ZY-LMVESMYS-260907-000011, check in assigned to Yujie | F14: 46288 | G14: FF48 | H14: did cover labels with yujie and repalletized the 10 pallets, updated in remarks in the system, and finished scanning, also organized , did measurements | P14: 46279 | T14: -in the morning checked dock and yard for containers before coming inside and clocking -spent 10 minutes on empties from Sunday (sent empty emails and notifications) -10 minutes writing containers on dock and checking what is taken over the weekend/Sunday -25 minutes on emails and chats, sheduling, rescheduling, followups -40 minutes? was also checking in containers while uploading photos of containers from the day before (uploaded 12） -30 minutes on labels printing and duplicates from containers scheduled in the morning. -updated maintenance sheet -spent about 30 minutes on TimeCard and sent email -unboxed and organized Amazon orders and list, corresponded with Wilson on things that said was delivered but was not seen in the office -spent about 30 minutes with upkeeping, emails of selling broken pallet, purchase new pallet, time correction, warming reports, cleaning invoice -10 minutes updating the white board -responded to work tickets -printed more labels and WR, scheudled around 12 additional containers for the rest of the week -noted machines down, compared machines, noted photos, sent emails, and added to maintnance sheet -uploaded 2 container photos in the afternoon | AG14: 0 | AH14: 480 | AI14: 0
A15: 46276 | B15: 3 | C15: 8 | D15: ZY-MGL-260908-000057 check in assigned to Yujie | F15: 46288 | G15: BP36 | H15: did cover labels with scanners and drivers, mareila, melany, tix, jefferson, scanned and put into system, did measurement of lwh in system and organized. | P15: 46280 | T15: -in the morning checked dock and yard for containers before coming inside and clocking in -accepted 15 containers throughtout the day, checking in the container, checking WR for updated locations, and taking pictures of POD -staple loading and unloading, making sure the correct number of putaways were done -sent empty emails, wecom, wechat notifications after the containers were unloaded -uploaded 12 containers and seal photos -broken OP emailed with Greg -Wecom, responses to WY in reference to returns, work tickets on a suborder that's not picked up by Saia -helped Yujie check in large Central suborder -helped Kiki with B2B and SOP of suborder pickups， how to write checked in suborder in KPI -check on Amazon supplies list, asked Isamel, notified Wilson of items that were not seen that said was delivered. Also mentioned to write a note on amazon deliveries for SLM, to be delivered to the back office since we found one by the metal gate -imput mistakes sent from Isamel -help deliver new vest to Sam inside warehouse -loaded a suborder -printed 7 container labels and WR, did duplicates -help check in interview (scanner and driver position) and direct them to Fedex area to see Amanda -printed return labels and list and gave to Pablo -WY chat request to check if return was recieved, checked order number, noted SKU, assigned to Pablo -get items ready for new scanner and new sriver starting the next day, inlcuding vests, walkie talkie, gloves, clipboard, pens | AG15: 0 | AH15: 480 | AI15: 0
A16: 46279 | B16: 4 | C16: 10 | D16: ZY-VRS-260910-000002, ZY-WY-SZYDJ-260908-000001, ZY-WY-SZYDJ-260906-000001, ZY-LMVESMYS-260909-000012, checked in assigned to Tix | F16: 46294 | G16: many orders (don't remember code), Amazon, Central, Green Pallets, and organize pallets with Sam | P16: 46281 | T16: -in the morning checked dock and yard for containers before coming inside and clocking in -accepted 22 containers throughtout the day, checking in the container, checking WR for updated locations, and taking pictures of POD -staple loading and unloading, making sure the correct number of putaways were done -10 minutes scheduling email (put onto calendar), responding to emails and work tickets, communicate with elsa in regards to expidited container -sent empty emails, wecom, wechat notifications after the containers were unloaded -报空empties from the day before -排号RXO 30minutes -recieved amazon package, organized, and updated list -checked and responded to work ticket for container FSCU7220860 in regards to BL-BGY002-BR-X-1-S -updated forklift list -went to back of warehouse to check for spaces to park new containers (roughtly 15-20 minutes) -printed 3 labels and did duplicates, for the ones that are scheduled thursday and friday -responded to work ticket on an expidited putaway container SEKU4652340 -uploaded 10 containers and seal photos from containers arrived the day of -showed Kiki how to do empties, putaway and how to do the checklist and write the whiteboard at the end of the day | AG16: 0 | AH16: 480 | AI16: 0
A17: 46279 | B17: 2 | C17: 8 | D17: ZY-LMVESMYS-260910-000006, ZY-LMVESMYS-260910-000008 check in assigned to Yujie | P17: 46282 | T17: -in the morning checked dock and yard for containers before coming inside and clocking in -accepted 14 containers throughtout the day, checking in the container, checking WR for updated locations, and taking pictures of POD -staple loading and unloading, making sure the correct number of putaways were done -added 9/17 containers from excel scheduled and imput into new WMS schedule system -emailed Max Global and Best in regards to missing container photos that were requested of the driver upon delivery (3468S, 9222Max) -transfered appointments in email onto schedule excel -talked with Jane and Isabella to see where we can update in the system, improvements/additions to system to better and effienctly accept containers/notice similar sku etc -noticed new system does not show duplicate SKU with old appointments -checked in with roofers that came to fix he rood, CB Rainkin, checked email and gave locations of where the problems were in the warehouse -explained to KIKI in regards to appointment and schedule, along with new schedule system introduced in the last meeting (15-20 minutes). -sent POD to SSR, due to large amount of drivers asking us to write POD and send over phone as opposed to them coming in (checked other dates, and average around 3 a day, but sometime would go upwards of 6 that we will write when SSR is delivering a lot of containers that day) -sent time correction email and added KIKI to email -scheduled new containers for 9/18 and the week after, adjusted email to notify trucking company in regards to new system -take interviewee to fedex ups area to see amanda -sent emails to RXO, BEST and SSR in regards to next weeks container -sent email for purchase new pallets -print 100 each of morning vc rac, afternoon vc rack, morning fedex rack, afternoon fedex rack -print 18 labels and WR for next week -emailed appointments coming next week (15-20 schedule emails) -did adjusted inventory in the system with Isabella, UETU8865229, change in system, import batch list, and sent email to customer (did this because putaway was complete) -answered 2 phone calls from trucking companies that their containers will arrive 4:10pm and 4:15pm, and a company aksing if container is empty and can come after close -uploaded 5 container photos and seal from the day of | AG17: 0 | AH17: 480 | AI17: 0
A18: 46279 | B18: 1 | C18: 5 | D18: ZY-WY-SWNT-260901-000041 checked in assigned to Ramiro | P18: 46283 | T18: -in the morning before coming in checked the docks and yard for containers to see if it match the list -stapled unloading and putaway sheets together -spent 10 minutes uploading 6 container and seal photos from yesterday -brought to Jane's attention that the arrival time was Beijing time, and if it would conflict with the container being marked late -printed some more labels for outbound area, ups/fedex vc/regular rack -responded to maintainco invoices, confirming the date and what is fixed from June (checked notebook) -write next week's containers on whiteboard -check in fox, for pest control and have him sign the sheet from the company -responded to work ticket and expidited container OOCU7930571 -redid some BEST RXO scheduling due to containers from 9/17 being on hold, there was 5 on hold -uploaded some more photos about 3 from the day before, 1 was missing, has contacted the company for photos since the driver was told (as noted on POD) but did not send (7752) - eventually sent and imported into system -distributed VCE checks to employees, they dropped off and said to give to employees -scheduled containers for the week after, did some adjustements to the time and repsonded to emails -called Meiya (trucking company) as they kept calling Amanda, and they just wanted to switch dates for containers delivery, informed them that the new system would mean they would need to correspond with the customer -helped direct two interviewees to Fedex area to be interviewed -updated amazon list and organized items that arrived -called vivian for container (7991) because driver parked at wrong dock | AG18: 0 | AH18: 480 | AI18: 0
A19: 46280 | B19: 26 | C19: 8 | D19: ZY-BHD-260902-000002 checked in assigned to Emerson | P19: 46286 | T19: -accepted containers throughtout the day, checking in the container, checking WR for updated locations, and taking pictures of POD -distributed VCE cheques to employess that were delivered last week -checked dock and yard for containers that are here and left over the weekend -printed new containers for Monday and did duplicates (5 new containers) -printed a new RXO container and did duplicates since it was not in the system -repsonded to XT on WeCom -sent email for selling broken pallet -sent warning report and time correction -added swing 52 to forlift list -updated machines and maintinance list, contacted wilson on who to contact due to it not being in the records and also what company for repairs in regards to light and fan -contacted Raymond Pengate for broken swing (52) -sent TimeCard email after confirming times in UAcess and adjusted for the employees Martha and Juan Perez -uploaded one container photo of seal and containers from Wechat -taught kiki how to upload photos from cell phone to WMS system -print 2 suborders and the picklists -print return putaway -did suborder preparation in the back with Isabella -scheduled containers manuallly in the system, communicated with oliva from Best in regards to containers going forward | AG19: 0 | AH19: 480 | AI19: 0
A20: 46280 | B20: 1 | C20: 10 | D20: ZY-LMVESMYS-260907-000001 checked in by Kiki, Mandy loaded suborder | P20: 46287 | T20: -checked dock and yard for containers -making sure it matched our checklist -printed and did duplicates of containers that were added after work (RXO) that are supposed to come today -reponded to a work document and also contacted Winona to contact the customer urgently to adjust the containers sku, due to the customer making an error, ended up adjusting the container FFAU2682664 RC since we could not delete the ones made in an error, so those would show up as discrepancies -completed work tickets, checked if systems' schedule match the excel schedule -matched RXO with schedule -sent email for missing screws on OP PO: 092126-04764 to Raymond -sent emails in reference to machines that are broken, forklift slm9, sent to maintainco -printed the remaining labels for the week, and did the duplicates -counted water delivered and taken empties -replied to emails and scheduling conflicts -went to the warehouse and prepared suborder pallets, labeling and replletizing | AG20: 0 | AH20: 480 | AI20: 0
A21: 46282 | B21: 4 | C21: 12 | D21: JR27, AP76, UO87, XW73 check in assigned to Oscar | P21: 46288 | T21: -checked the dock and yard for containers and made sure to matched the container form yesterday afternoon. Gave what I have to KiKi -went training with Isabella and Scanners in teh warehouse to see how to label pallets/repalletize in the afternoon -did calcuations for suborder MQ67, the weight and finished in the system -checked emails, reponded to any necessar, checked Wecom and Wechat -connected 4 airtags to 4 large PDA's and also assigned 2 to the new drivers -organized the office and the items -adjusted Martha's 9/21 and 9/22 time in UAcess -organized forklift list 'OP Admin Checklist | AG21: 0 | AH21: 480 | AI21: 0
A22: 46286 | B22: 1 | C22: 5 | D22: PD93 check in assigned to Yujie | P22: 46289 | T22: -checked the contianers on dock and in the yard and gave it to KiKi when I came in -have people sign the sheet after saefty meeting -respond to emails -updated machines and mainteniance list -organized the office and storage room -bought tape measure on amazon -responded to work tickets -sent time correction forms -oraganize RXO containers, and set how many coming next week -printed rxo SSR containers, did duplicates, and organized -sent cleaning invoice email -organize amazon orders and updated the list -printed bhd containers and did duplicates | AG22: 0 | AH22: 480 | AI22: 0
A23: 46287 | B23: 5 | C23: 8 | D23: ZY-BHD-260821-000003 check in assigned to Yujie | P23: 46290 | T23: -checked docks for containers on dock and containers in the yard and gave post it note to KiKi -taught KiKi some more about accepting containers and what needs to be done as she checked containers on friday and how sunday works with the rotating teams -checked work tickets and responded to some that can be responded to, including if certain SKU can be scanned and used the scanner -checked what was low in the office and bought them on amazon (binder clips, cups for water) -trained with Isabella for new picking KPI method, then inserted picking KPI to excel -organized storage room, desk and office area, took out halloween decorations -organized new amazon packages that arrived and updated on list -printed more ups/fedex rack labels for outbound -added new driver account (Carlos) into UAcess, asked jacky to create driver account -sent bought new pallet and sold broken pallet emails and attachments -directed interviewee to amanda office, directed interviewee to fedex area -repsonded to emails and checked machines and maintenance sheet -did some remaining printing of labels and did duplicates for next week -organized office supplies, and ordered what is low on amazon -wrote next week's container schedule on the white board | AG23: 0 | AH23: 480 | AI23: 0
